<?xml version="1.0" ?>

<robot name="robot" xmlns:xacro="http://ros.org/wiki/xacro">
  <xacro:include filename="$(find romrobots_description)/urdf/common_properties.urdf.xacro"/>
  
  <xacro:macro name="robot">
    <link name="base_footprint"/>
    <joint name="base_joint" type="fixed">
      <origin xyz="0 0 0.0102" rpy="0 0 0" />
      <parent link="base_footprint"/>
      <child link="base_link" />
    </joint>
    <link name="base_link">
      <visual>
        <geometry>
          <!-- new mesh -->
          <cylinder length="0.24" radius="0.24" />
        </geometry>
        <!-- <origin xyz="0 0 0.15" rpy="0 0 0"/> -->
        <origin xyz="0 0 0.25" rpy="0 0 0" />
        <material name="black"/>
      </visual>
      <collision name="base">
        <geometry>
          <cylinder length="0.24" radius="0.24"/>
        </geometry>
        <!-- <origin xyz="0.0 0 0.15" rpy="0 0 0"/> -->
        <origin xyz="0 0 0.25" rpy="0 0 0" />
      </collision>
      <inertial>
        <origin xyz="0.01 0 0"/>
        <mass value="2.4"/>
        <inertia ixx="0.019995" ixy="0.0" ixz="0.0"
                 iyy="0.019995" iyz="0.0"
                 izz="0.03675" />
      </inertial>
    </link>

    <joint name="left_wheel_joint" type="continuous">
      <parent link="base_link"/>
      <child link="left_wheel_link"/>
      <!-- <origin xyz="0.00 ${0.333/2} 0.02" rpy="${-M_PI/2} 0 0"/> -->
      <origin xyz="0.00 ${0.333/2} 0.05" rpy="${-M_PI/2} 0 0" />
      <axis xyz="0 0 1"/>
    </joint>
    <link name="left_wheel_link">
      <visual>
        <geometry>
          <cylinder length="0.0276" radius="0.0705" />
        </geometry>
        <!-- <origin xyz="0 -0.03 0" rpy="0 0 0"/> -->
        <origin xyz="0 0 0" rpy="0 0 0"/>
        <material name="black"/>
      </visual>
      <collision>
        <geometry>
          <sphere radius="0.0705"/>
        </geometry>
        <origin rpy="0 0 0" xyz="0 0 0"/>
      </collision>
      <inertial>
        <mass value="0.01" />
        <origin xyz="0 0 0" />
        <inertia ixx="0.001" ixy="0.0" ixz="0.0"
                 iyy="0.001" iyz="0.0"
                 izz="0.001" />
      </inertial>
    </link>

    <joint name="right_wheel_joint" type="continuous">
      <parent link="base_link"/>
      <child link="right_wheel_link"/>
      <origin xyz="0.00 -${0.333/2} 0.05" rpy="${-M_PI/2} 0 0"/>
      <axis xyz="0 0 1"/>
    </joint>
    <link name="right_wheel_link">
      <visual>
        <geometry>
          <cylinder length="0.0276" radius="0.0705" />
        </geometry>
        <!-- <origin xyz="0 -0.03 0" rpy="0 0 0"/> -->
        <origin xyz="0 0 0" rpy="0 0 0"/>
        <material name="black"/>
      </visual>
      <collision>
        <geometry>
          <sphere radius="0.0705"/>
        </geometry>
        <origin rpy="0 0 0" xyz="0 0 0"/>
      </collision>
      <inertial>
        <mass value="0.01" />
        <origin xyz="0 0 0" />
        <inertia ixx="0.001" ixy="0.0" ixz="0.0"
                 iyy="0.001" iyz="0.0"
                 izz="0.001" />
      </inertial>
    </link>

<!-- NEW CASTER -->
  <link name="front_caster_ball">
    <inertial>
      <mass value="0.1"/>  <!-- Adjust the mass as per your robot's specs -->
      <inertia ixx="0.001" iyy="0.001" izz="0.001" ixy="0.0" ixz="0.0" iyz="0.0"/>
    </inertial>

    <visual>
      <geometry>
        <sphere radius="0.02"/>  <!-- Radius of the caster ball -->
      </geometry>
      <material name="grey">
        <color rgba="0.5 0.5 0.5 1.0"/>
      </material>
    </visual>

    <collision>
      <geometry>
        <sphere radius="0.02"/>  <!-- Same radius as the visual element -->
      </geometry>
    </collision>
  </link>

  <joint name="front_caster_ball_joint" type="fixed">
    <parent link="base_link"/>
    <child link="front_caster_ball"/>
    <origin xyz="0.16676 0 0.01" rpy="0 0 0"/>  <!-- z axis  -->
  </joint>
  
  <link name="back_caster_ball">
    <inertial>
      <mass value="0.1"/>  <!-- Adjust the mass as per your robot's specs -->
       <inertia ixx="0.001" iyy="0.001" izz="0.001" ixy="0.0" ixz="0.0" iyz="0.0"/>
    </inertial>

    <visual>
      <geometry>
        <sphere radius="0.02"/>  <!-- Radius of the caster ball -->
      </geometry>
      <material name="grey">
        <color rgba="0.5 0.5 0.5 1.0"/>
      </material>
    </visual>

    <collision>
      <geometry>
        <sphere radius="0.02"/>  <!-- Same radius as the visual element -->
      </geometry>
    </collision>
  </link>

  <joint name="back_caster_ball_joint" type="fixed">
    <parent link="base_link"/>
    <child link="back_caster_ball"/>
    <origin xyz="-0.16676 0 0.01" rpy="0 0 0"/>  <!-- z axis  -->
  </joint>
<!-- caster end -->
    <joint name="imu_joint" type="fixed">
      <parent link="base_link"/>
      <child link="imu_link"/>
      <origin xyz="0 0 0.268" rpy="0 0 0"/>
    </joint>

    <link name="imu_link">
      <visual>
        <origin xyz="0 0 0.0" rpy="0 0 0"/>
        <geometry>
          <box size="0.03 0.02 0.02"/>
        </geometry>
        <material name="red"/>
      </visual>
    </link>

    <joint name="laser_joint" type="fixed">
      <parent link="base_link"/>
      <child link="laser_link"/>
      <!-- <origin xyz="0.156 0 0.275" rpy="0 0 0"/> -->
      <origin  xyz="0.256 0 0.275" rpy="0 0 0"/>
    </joint>

    <link name="laser_link">
      <visual>
        <origin xyz="0 0 0.0" rpy="0 0 0"/>
        <geometry>
          <box size="0.05 0.05 0.05"/>
        </geometry>
        <material name="grey_blue"/>
      </visual>

      <collision>
        <origin xyz="0.015 0 -0.0065" rpy="0 0 0"/>
        <geometry>
          <cylinder length="0.0315" radius="0.055"/>
        </geometry>
      </collision>

      <!-- <inertial>
        <mass value="0.114" />
        <origin xyz="0 0 0" />
        <inertia ixx="0.001" ixy="0.0" ixz="0.0"
                 iyy="0.001" iyz="0.0"
                 izz="0.001" />
      </inertial> -->
    </link>

    <!-- 3D CAM_Top -->
  <joint name="cam3d_top_joint" type="fixed">
      <parent link="base_link"/>
      <child link="cam3d_top_link"/>
      <origin xyz="0.15 0 0.8" rpy="0 0 0"/>
  </joint>

  <link name="cam3d_top_link">
      <visual>
        <origin xyz="0 0 0.0" rpy="0 0 0"/>
        <geometry>
          <box size="0.03 0.02 0.02"/>
        </geometry>
        <material name="blue"/>
      </visual>
  </link>
    
  </xacro:macro>
</robot>
