<?xml version="1.0" ?>
<!-- =================================================================================== -->
<!-- |    This document was autogenerated by xacro from yoyo_complete.xacro            | -->
<!-- |    EDITING THIS FILE BY HAND IS NOT RECOMMENDED                                 | -->
<!-- =================================================================================== -->
<robot name="yoyo_standalone" xmlns:controller="http://playerstage.sourceforge.net/gazebo/xmlschema/#controller" xmlns:interface="http://playerstage.sourceforge.net/gazebo/xmlschema/#interface" xmlns:sensor="http://playerstage.sourceforge.net/gazebo/xmlschema/#sensor">
  <material name="white">
    <color rgba="1 1 1 0.8"/>
  </material>
  <material name="grey">
    <color rgba="0.5 0.5 0.5 1"/>
  </material>
  <material name="light_grey">
    <color rgba="0.6 0.6 0.6 0.7"/>
  </material>
  <material name="dark_grey">
    <color rgba="0.3 0.3 0.3 0.7"/>
  </material>
  <material name="black">
    <color rgba="0.1 0.1 0.1 0.8"/>
  </material>
  <material name="red">
    <color rgba="1 0 0 0.8"/>
  </material>
  <material name="green">
    <color rgba="0.0 0.8 0.0 1"/>
  </material>
  <material name="blue">
    <color rgba="0.0 0.0 1.0 1"/>
  </material>
  <material name="grey_blue">
    <color rgba="0.4 0.4 1.0 0.8"/>
  </material>
  <material name="orange">
    <color rgba="1.0 0.7 0.0 1"/>
  </material>
  <ros2_control name="GazeboSystem" type="system">
    <hardware>
      <plugin>gazebo_ros2_control/GazeboSystem</plugin>
    </hardware>
    <joint name="left_wheel_joint">
      <command_interface name="velocity">
        <param name="min">-1</param>
        <param name="max">1</param>
      </command_interface>
      <state_interface name="velocity"/>
      <state_interface name="position"/>
    </joint>
    <joint name="right_wheel_joint">
      <command_interface name="velocity">
        <param name="min">-1</param>
        <param name="max">1</param>
      </command_interface>
      <state_interface name="velocity"/>
      <state_interface name="position"/>
    </joint>
  </ros2_control>
  <gazebo>
    <plugin filename="libgazebo_ros2_control.so" name="gazebo_ros2_control">
      <robot_param>robot_description</robot_param>
      <robot_param_node>robot_state_publisher</robot_param_node>
      <parameters>/home/mr_robot/test_ws/src/bobo_simulation/simulation_packages/romrobots_description/config/yoyo_controllers.yaml</parameters>
      <!-- Output -->
      <odometry_frame>odom</odometry_frame>
      <robot_base_frame>base_footprint</robot_base_frame>
      <publish_odom>true</publish_odom>
      <publish_odom_tf>true</publish_odom_tf>
      <publish_wheel_tf>true</publish_wheel_tf>
    </plugin>
  </gazebo>
  <gazebo reference="left_wheel_link">
    <material>Gazebo/Black</material>
    <kp>1000000.0</kp>
    <kd>10.0</kd>
    <mu1>1.2</mu1>
    <mu2>1.2</mu2>
    <fdir1>1 0 0</fdir1>
    <maxVel>0.5</maxVel>
    <minDepth>0.00</minDepth>
    <!-- <mu1>1.3</mu1>
      <mu2>1.3</mu2> -->
  </gazebo>
  <gazebo reference="right_wheel_link">
    <material>Gazebo/Black</material>
    <kp>1000000.0</kp>
    <kd>10.0</kd>
    <mu1>1.2</mu1>
    <mu2>1.2</mu2>
    <fdir1>1 0 0</fdir1>
    <maxVel>0.5</maxVel>
    <minDepth>0.00</minDepth>
    <!-- <mu1>1.3</mu1>
      <mu2>1.3</mu2> -->
  </gazebo>
  <gazebo reference="caster_front_link">
    <material>Gazebo/Black</material>
    <!-- <kp>1000000.0</kp>
      <kd>10.0</kd>
      <mu1>1.2</mu1>
      <mu2>1.2</mu2>
      <fdir1>1 0 0</fdir1>
      <maxVel>0.5</maxVel>
      <minDepth>0.00</minDepth> -->
    <mu1>1.0</mu1>
    <mu2>0.05</mu2>
  </gazebo>
  <gazebo reference="caster_back_link">
    <material>Gazebo/Black</material>
    <!-- <kp>1000000.0</kp>
      <kd>10.0</kd>
      <mu1>1.2</mu1>
      <mu2>1.2</mu2>
      <fdir1>1 0 0</fdir1>
      <maxVel>0.5</maxVel>  
      <minDepth>0.00</minDepth> -->
    <mu1>1.0</mu1>
    <mu2>0.05</mu2>
  </gazebo>
  <gazebo reference="imu_link">
    <gravity>true</gravity>
    <sensor name="imu_sensor" type="imu">
      <always_on>true</always_on>
      <update_rate>20</update_rate>
      <visualize>true</visualize>
      <topic>/imu</topic>
      <plugin filename="libgazebo_ros_imu_sensor.so" name="imu">
        <topicName>imu</topicName>
        <bodyName>imu_link</bodyName>
        <updateRateHZ>10.0</updateRateHZ>
        <gaussianNoise>0.0</gaussianNoise>
        <xyzOffset>0 0 0</xyzOffset>
        <rpyOffset>0 0 0</rpyOffset>
        <frameName>imu_link</frameName>
        <initialOrientationAsReference>false</initialOrientationAsReference>
      </plugin>
      <pose>0 0 0 0 0 0</pose>
    </sensor>
  </gazebo>
  <!-- TOP CAMERA -->
  <joint name="camera_optical_joint" type="fixed">
    <parent link="cam3d_top_link"/>
    <child link="camera_link_optical"/>
    <origin rpy="-1.57075 0 -1.57075" xyz="0 0 0"/>
    <!-- ${-pi/2} -->
  </joint>
  <link name="camera_link_optical"/>
  <gazebo reference="cam3d_top_link">
    <material>Gazebo/Blue</material>
    <sensor name="camera_top" type="depth">
      <pose>0 0 0 0 0 0</pose>
      <visualize>true</visualize>
      <update_rate>10</update_rate>
      <camera>
        <horizontal_fov>1.089</horizontal_fov>
        <image>
          <format>B8G8R8</format>
          <width>640</width>
          <height>480</height>
        </image>
        <clip>
          <near>0.05</near>
          <far>8.0</far>
        </clip>
      </camera>
      <plugin filename="libgazebo_ros_camera.so" name="camera_controller_top">
        <frame_name>camera_link_optical</frame_name>
        <min_depth>0.1</min_depth>
        <max_depth>50</max_depth>
      </plugin>
    </sensor>
  </gazebo>
  <gazebo reference="laser_link">
    <material>Gazebo/Red</material>
    <sensor name="laser" type="ray">
      <pose>0 0 0 0 0 0</pose>
      <visualize>true</visualize>
      <update_rate>20</update_rate>
      <ray>
        <scan>
          <horizontal>
            <samples>360</samples>
            <resolution>1</resolution>
            <min_angle>-2.3562</min_angle>
            <!-- -3.14 -->
            <max_angle>2.3562</max_angle>
            <!-- 3.14 -->
          </horizontal>
        </scan>
        <range>
          <min>0.5</min>
          <!-- 0.3 -->
          <max>12</max>
          <!-- 12 -->
          <resolution>0.01</resolution>
        </range>
      </ray>
      <plugin filename="libgazebo_ros_ray_sensor.so" name="laser_controller">
        <ros>
          <argument>~/out:=scan</argument>
        </ros>
        <output_type>sensor_msgs/LaserScan</output_type>
        <frame_name>laser_link</frame_name>
      </plugin>
    </sensor>
  </gazebo>
  <link name="base_footprint"/>
  <joint name="base_joint" type="fixed">
    <origin rpy="0 0 0" xyz="0 0 0.0102"/>
    <parent link="base_footprint"/>
    <child link="base_link"/>
  </joint>
  <link name="base_link">
    <inertial>
      <origin rpy="0 0 0" xyz="0.0052125 -1.3478E-05 0.19649"/>
      <mass value="1.7335"/>
      <inertia ixx="0.016138" ixy="-2.6556E-08" ixz="-0.00032505" iyy="0.018981" iyz="2.2146E-08" izz="0.031833"/>
    </inertial>
    <visual>
      <origin rpy="0 0 0" xyz="0 0 0"/>
      <geometry>
        <mesh filename="/home/mr_robot/test_ws/src/bobo_simulation/simulation_packages/romrobots_description/meshes/base_link.STL"/>
      </geometry>
      <material name="">
        <color rgba="0.75294 0.75294 0.75294 1"/>
      </material>
    </visual>
    <collision>
      <origin rpy="0 0 0" xyz="0 0 0"/>
      <geometry>
        <mesh filename="/home/mr_robot/test_ws/src/bobo_simulation/simulation_packages/romrobots_description/meshes/base_link.STL"/>
      </geometry>
    </collision>
  </link>
  <link name="right_wheel_link">
    <inertial>
      <origin rpy="0 0 0" xyz="-1.6048E-09 0.0026108 -2.1412E-10"/>
      <mass value="1.1347"/>
      <inertia ixx="0.0021438" ixy="1.9702E-09" ixz="8.2955E-12" iyy="0.0037129" iyz="7.9733E-10" izz="0.0021438"/>
    </inertial>
    <visual>
      <origin rpy="0 0 0" xyz="0 0 0"/>
      <geometry>
        <mesh filename="/home/mr_robot/test_ws/src/bobo_simulation/simulation_packages/romrobots_description/meshes/right_wheel_link.STL"/>
      </geometry>
      <material name="">
        <color rgba="1 1 1 1"/>
      </material>
    </visual>
    <collision>
      <origin rpy="0 0 0" xyz="0 0 0"/>
      <geometry>
        <mesh filename="/home/mr_robot/test_ws/src/bobo_simulation/simulation_packages/romrobots_description/meshes/right_wheel_link.STL"/>
      </geometry>
    </collision>
  </link>
  <joint name="right_wheel_joint" type="continuous">
    <origin rpy="0 0 0" xyz="-0.000499999999999182 -0.179709309933579 0.085"/>
    <parent link="base_link"/>
    <child link="right_wheel_link"/>
    <axis xyz="0 1 0"/>
  </joint>
  <link name="left_wheel_link">
    <inertial>
      <origin rpy="0 0 0" xyz="1.4724E-09 -0.0026108 -6.7344E-10"/>
      <mass value="1.1347"/>
      <inertia ixx="0.0021438" ixy="1.6515E-09" ixz="-1.1089E-11" iyy="0.0037129" iyz="-1.3379E-09" izz="0.0021438"/>
    </inertial>
    <visual>
      <origin rpy="0 0 0" xyz="0 0 0"/>
      <geometry>
        <mesh filename="/home/mr_robot/test_ws/src/bobo_simulation/simulation_packages/romrobots_description/meshes/left_wheel_link.STL"/>
      </geometry>
      <material name="">
        <color rgba="1 1 1 1"/>
      </material>
    </visual>
    <collision>
      <origin rpy="0 0 0" xyz="0 0 0"/>
      <geometry>
        <mesh filename="/home/mr_robot/test_ws/src/bobo_simulation/simulation_packages/romrobots_description/meshes/left_wheel_link.STL"/>
      </geometry>
    </collision>
  </link>
  <joint name="left_wheel_joint" type="continuous">
    <origin rpy="0 0 0" xyz="-0.000500000000000396 0.179709309933579 0.085"/>
    <parent link="base_link"/>
    <child link="left_wheel_link"/>
    <axis xyz="0 1 0"/>
  </joint>
  <!-- NEW CASTER -->
  <link name="front_caster_ball">
    <inertial>
      <mass value="0.1"/>
      <!-- Adjust the mass as per your robot's specs -->
      <inertia ixx="0.001" ixy="0.0" ixz="0.0" iyy="0.001" iyz="0.0" izz="0.001"/>
    </inertial>
    <visual>
      <geometry>
        <sphere radius="0.02"/>
        <!-- Radius of the caster ball -->
      </geometry>
      <material name="grey">
        <color rgba="0.5 0.5 0.5 1.0"/>
      </material>
    </visual>
    <collision>
      <geometry>
        <sphere radius="0.02"/>
        <!-- Same radius as the visual element -->
      </geometry>
    </collision>
  </link>
  <joint name="front_caster_ball_joint" type="fixed">
    <parent link="base_link"/>
    <child link="front_caster_ball"/>
    <origin rpy="0 0 0" xyz="0.16676 0 0.0210"/>
    <!-- z axis 0.02 နဲ့ 0.03 ကြား -->
  </joint>
  <link name="back_caster_ball">
    <inertial>
      <mass value="0.1"/>
      <!-- Adjust the mass as per your robot's specs -->
      <inertia ixx="0.001" ixy="0.0" ixz="0.0" iyy="0.001" iyz="0.0" izz="0.001"/>
    </inertial>
    <visual>
      <geometry>
        <sphere radius="0.02"/>
        <!-- Radius of the caster ball -->
      </geometry>
      <material name="grey">
        <color rgba="0.5 0.5 0.5 1.0"/>
      </material>
    </visual>
    <collision>
      <geometry>
        <sphere radius="0.02"/>
        <!-- Same radius as the visual element -->
      </geometry>
    </collision>
  </link>
  <joint name="back_caster_ball_joint" type="fixed">
    <parent link="base_link"/>
    <child link="back_caster_ball"/>
    <origin rpy="0 0 0" xyz="-0.16676 0 0.0210"/>
    <!-- z axis 0.02 နဲ့ 0.03 ကြား -->
  </joint>
  <!-- ROM ADD -->
  <!-- LASER -->
  <joint name="laser_joint" type="fixed">
    <parent link="base_link"/>
    <child link="laser_link"/>
    <!-- <origin xyz="0.156 0 0.275" rpy="0 0 0"/> -->
    <origin rpy="0 0 0" xyz="0.256 0 0.275"/>
  </joint>
  <link name="laser_link">
    <visual>
      <origin rpy="0 0 0" xyz="0 0 0.0"/>
      <geometry>
        <box size="0.05 0.05 0.05"/>
      </geometry>
      <material name="grey_blue"/>
    </visual>
    <collision>
      <origin rpy="0 0 0" xyz="0.015 0 -0.0065"/>
      <geometry>
        <cylinder length="0.0315" radius="0.055"/>
      </geometry>
    </collision>
    <!-- <inertial>
        <mass value="0.114" />
        <origin xyz="0 0 0" />
        <inertia ixx="0.001" ixy="0.0" ixz="0.0"
                 iyy="0.001" iyz="0.0"
                 izz="0.001" />
      </inertial> -->
  </link>
  <!-- 3D CAM_Top -->
  <joint name="cam3d_top_joint" type="fixed">
    <parent link="base_link"/>
    <child link="cam3d_top_link"/>
    <origin rpy="0 0 0" xyz="0.15 0 0.8"/>
  </joint>
  <link name="cam3d_top_link">
    <visual>
      <origin rpy="0 0 0" xyz="0 0 0.0"/>
      <geometry>
        <box size="0.03 0.02 0.02"/>
      </geometry>
      <material name="blue"/>
    </visual>
  </link>
  <!-- IMU -->
  <joint name="imu_joint" type="fixed">
    <parent link="base_link"/>
    <child link="imu_link"/>
    <origin rpy="0 0 0" xyz="0 0 0.268"/>
  </joint>
  <link name="imu_link">
    <visual>
      <origin rpy="0 0 0" xyz="0 0 0.0"/>
      <geometry>
        <box size="0.03 0.02 0.02"/>
      </geometry>
      <material name="red"/>
    </visual>
  </link>
</robot>
