<?xml version="1.0" encoding="utf-8"?>
<robot name="robot" xmlns:xacro="http://ros.org/wiki/xacro">
  <xacro:include filename="$(find romrobots_description)/urdf/common_properties.urdf.xacro"/>


  <xacro:macro name="robot">

  <link name="base_footprint"/>
  <joint name="base_joint" type="fixed">
    <origin xyz="0 0 0.0102" rpy="0 0 0" />
    <parent link="base_footprint"/>
    <child link="base_link" />
  </joint>

  <link
    name="base_link">
    <inertial>
      <origin
        xyz="0.0052125 -1.3478E-05 0.19649"
        rpy="0 0 0" />
      <mass
        value="1.7335" />
      <inertia
        ixx="0.016138"
        ixy="-2.6556E-08"
        ixz="-0.00032505"
        iyy="0.018981"
        iyz="2.2146E-08"
        izz="0.031833" />
    </inertial>
    <visual>
      <origin
        xyz="0 0 0"
        rpy="0 0 0" />
      <geometry>
        <mesh
          filename="package://romrobots_description/meshes/base_link.STL" />
      </geometry>
      <material
        name="">
        <color
          rgba="0.75294 0.75294 0.75294 1" />
      </material>
    </visual>
    <collision>
      <origin
        xyz="0 0 0"
        rpy="0 0 0" />
      <geometry>
        <mesh
          filename="package://romrobots_description/meshes/base_link.STL" />
      </geometry>
    </collision>
  </link>
  <link
    name="right_wheel_link">
    <inertial>
      <origin
        xyz="-1.6048E-09 0.0026108 -2.1412E-10"
        rpy="0 0 0" />
      <mass
        value="1.1347" />
      <inertia
        ixx="0.0021438"
        ixy="1.9702E-09"
        ixz="8.2955E-12"
        iyy="0.0037129"
        iyz="7.9733E-10"
        izz="0.0021438" />
    </inertial>
    <visual>
      <origin
        xyz="0 0 0"
        rpy="0 0 0" />
      <geometry>
        <mesh
          filename="package://romrobots_description/meshes/right_wheel_link.STL" />
      </geometry>
      <material
        name="">
        <color
          rgba="1 1 1 1" />
      </material>
    </visual>
    <collision>
      <origin
        xyz="0 0 0"
        rpy="0 0 0" />
      <geometry>
        <mesh
          filename="package://romrobots_description/meshes/right_wheel_link.STL" />
      </geometry>
    </collision>
  </link>
  <joint
    name="right_wheel_joint"
    type="continuous">
    <origin
      xyz="-0.000499999999999182 -0.179709309933579 0.085"
      rpy="0 0 0" />
    <parent
      link="base_link" />
    <child
      link="right_wheel_link" />
    <axis
      xyz="0 1 0" />
  </joint>
  <link
    name="left_wheel_link">
    <inertial>
      <origin
        xyz="1.4724E-09 -0.0026108 -6.7344E-10"
        rpy="0 0 0" />
      <mass
        value="1.1347" />
      <inertia
        ixx="0.0021438"
        ixy="1.6515E-09"
        ixz="-1.1089E-11"
        iyy="0.0037129"
        iyz="-1.3379E-09"
        izz="0.0021438" />
    </inertial>
    <visual>
      <origin
        xyz="0 0 0"
        rpy="0 0 0" />
      <geometry>
        <mesh
          filename="package://romrobots_description/meshes/left_wheel_link.STL" />
      </geometry>
      <material
        name="">
        <color
          rgba="1 1 1 1" />
      </material>
    </visual>
    <collision>
      <origin
        xyz="0 0 0"
        rpy="0 0 0" />
      <geometry>
        <mesh
          filename="package://romrobots_description/meshes/left_wheel_link.STL" />
      </geometry>
    </collision>
  </link>
  <joint
    name="left_wheel_joint"
    type="continuous">
    <origin
      xyz="-0.000500000000000396 0.179709309933579 0.085"
      rpy="0 0 0" />
    <parent
      link="base_link" />
    <child
      link="left_wheel_link" />
    <axis
      xyz="0 1 0" />
  </joint>
  
    <!-- NEW CASTER -->
  <link name="front_caster_ball">
    <inertial>
      <mass value="0.1"/>  <!-- Adjust the mass as per your robot's specs -->
      <inertia ixx="0.001" iyy="0.001" izz="0.001" ixy="0.0" ixz="0.0" iyz="0.0"/>
    </inertial>

    <visual>
      <geometry>
        <sphere radius="0.02"/>  <!-- Radius of the caster ball -->
      </geometry>
      <material name="grey">
        <color rgba="0.5 0.5 0.5 1.0"/>
      </material>
    </visual>

    <collision>
      <geometry>
        <sphere radius="0.02"/>  <!-- Same radius as the visual element -->
      </geometry>
    </collision>
  </link>

  <joint name="front_caster_ball_joint" type="fixed">
    <parent link="base_link"/>
    <child link="front_caster_ball"/>
    <origin xyz="0.16676 0 0.0210" rpy="0 0 0"/>  <!-- z axis -->
  </joint>
  
  <link name="back_caster_ball">
    <inertial>
      <mass value="0.1"/>  <!-- Adjust the mass as per your robot's specs -->
       <inertia ixx="0.001" iyy="0.001" izz="0.001" ixy="0.0" ixz="0.0" iyz="0.0"/>
    </inertial>

    <visual>
      <geometry>
        <sphere radius="0.02"/>  <!-- Radius of the caster ball -->
      </geometry>
      <material name="grey">
        <color rgba="0.5 0.5 0.5 1.0"/>
      </material>
    </visual>

    <collision>
      <geometry>
        <sphere radius="0.02"/>  <!-- Same radius as the visual element -->
      </geometry>
    </collision>
  </link>

  <joint name="back_caster_ball_joint" type="fixed">
    <parent link="base_link"/>
    <child link="back_caster_ball"/>
    <origin xyz="-0.16676 0 0.0210" rpy="0 0 0"/>  <!-- z axis -->
  </joint>

  <!-- ROM ADD -->
  <!-- LASER -->
  <joint name="laser_joint" type="fixed">
      <parent link="base_link"/>
      <child link="laser_link"/>
      <!-- <origin xyz="0.156 0 0.275" rpy="0 0 0"/> -->
      <origin  xyz="0.256 0 0.275" rpy="0 0 0"/>
    </joint>

    <link name="laser_link">
      <visual>
        <origin xyz="0 0 0.0" rpy="0 0 0"/>
        <geometry>
          <box size="0.05 0.05 0.05"/>
        </geometry>
        <material name="grey_blue"/>
      </visual>

      <collision>
        <origin xyz="0.015 0 -0.0065" rpy="0 0 0"/>
        <geometry>
          <cylinder length="0.0315" radius="0.055"/>
        </geometry>
      </collision>

      <!-- <inertial>
        <mass value="0.114" />
        <origin xyz="0 0 0" />
        <inertia ixx="0.001" ixy="0.0" ixz="0.0"
                 iyy="0.001" iyz="0.0"
                 izz="0.001" />
      </inertial> -->
  </link>

  <!-- 3D CAM_Top -->
  <joint name="cam3d_top_joint" type="fixed">
      <parent link="base_link"/>
      <child link="cam3d_top_link"/>
      <origin xyz="0.15 0 0.8" rpy="0 0 0"/>
  </joint>

  <link name="cam3d_top_link">
      <visual>
        <origin xyz="0 0 0.0" rpy="0 0 0"/>
        <geometry>
          <box size="0.03 0.02 0.02"/>
        </geometry>
        <material name="blue"/>
      </visual>
  </link>

  <!-- IMU -->
  <joint name="imu_joint" type="fixed">
      <parent link="base_link"/>
      <child link="imu_link"/>
      <origin xyz="0 0 0.268" rpy="0 0 0"/>
    </joint>

    <link name="imu_link">
      <visual>
        <origin xyz="0 0 0.0" rpy="0 0 0"/>
        <geometry>
          <box size="0.03 0.02 0.02"/>
        </geometry>
        <material name="red"/>
      </visual>
    </link>

  </xacro:macro>
</robot>